Workbook

Sheet Follow up
D1: LABOR | E1: =COUNTIFS(I3:I1263, "Labor", V3:V1263, "Em andamento") -> 80 | G1: MAKE | H1: =COUNTIFS(I3:I1263, "make", V3:V1263, "Em andamento") -> 11 | I1: BUY | J1: =COUNTIFS(I3:I1263, "BUY", V3:V1263, "Em andamento") -> 115 | K1: MAKE / BUY | L1: =COUNTIFS(I3:I1263, "make/buy", V3:V1263, "Em andamento") -> 172 | M1: EM DEFINIÇÃO | N1: =COUNTIFS(I3:I1263, "em definição") -> 179 | O1: TOTAL | P1: =E1+H1+J1+L1+N1 -> 557 | Q1: FOLLOW-UP COMAU DO BRASIL
A2: Cliente | B2: Projeto WBS | C2: Linha / OP | D2: Descrição | E2: Transmissão / Eventual | F2: Rev. | G2: Data da criação | H2: Observação | I2: Make / Buy | J2: Data de inicio | K2: Pedido de compra | L2: Fornecedor | M2: Data entrega Fornecedor | N2: Reprogramação Fornecedor | O2: Data entrega final - MFG | P2: Status Geral % | Q2: Valor total | R2: Qtd Hr | S2: Resp.Follow-up | T2: Nota Fiscal | U2: Comercial | V2: Status | W2: Local de entrega | X2: Prioridade
A3: VW | B3: BRBCBBB37 | C3: UB2 e STW - BL02 | D3: SUPORTE MALA | E3: BB37-VW-ANCH-STW-UB2-0002-2025 | F3: 1 | G3: 46006 | H3: 26/01 Obs: Esta aprovado o adicional. Por favor seguir.... Compras irá enviar o pedido. Por favor, considere a folha em anexo com a nova quantidade pelo SCL Diego. 26/01- Liberado 2D. 26/01 - Rev01- Atualizado qtd ., de 74 par a76. | I3: Buy | J3: 46046 | L3: METALURGICA GRANATO | O3: 46068 | P3: 1 | R3: =Q3/89.23 -> 0 | S3: =IFERROR(VLOOKUP(L3,'Responsáveis'!$A$3:$B$140,2,FALSE),"NE") -> jadiel | U3: NÃO | V3: Em andamento | W3: Betim
A4: VW | B4: BRBCBBB37 | C4: STW | D4: DISPOSITIVO GEO | E4: BB37-VW-ANCH-STW-UB2-0003-2025 | F4: 0 | G4: 46011 | H4: 26/01- Obs: Aprovado pedido pelo Marcelo por e-mail sem PO. 06/01 - Liberado 2D. | I4: Labor | J4: 46038 | L4: TITAN | M4: 46108 | N4: 46080 | O4: 46093 | P4: 0.3 | R4: =Q4/89.23 -> 0 | S4: =IFERROR(VLOOKUP(L4,'Responsáveis'!$A$3:$B$140,2,FALSE),"NE") -> Rudnei | U4: SIM | V4: Em andamento
A5: VW | B5: BRBCBBB37 | C5: ST2130 | D5: DISPOSITIVO GEO | E5: BB37-VW-ANCH-STW-UB2-0004-2025 | F5: 0 | G5: 46011 | H5: 06/01 - Liberado 2D. | I5: Make/Buy | J5: 46034 | K5: CONTRATO | L5: BGB | M5: 46087 | N5: 46087 | O5: 46094 | P5: 0.3 | Q5: 109000 | R5: =Q5/89.23 -> 1221.5623 | S5: =IFERROR(VLOOKUP(L5,'Responsáveis'!$A$3:$B$140,2,FALSE),"NE") -> Rudnei | U5: SIM | V5: Em andamento | W5: Santo André
A6: VW | B6: BRBCBBB37 | C6: ST2130 | D6: GRIPPER GEO_STW | E6: BB37-VW-ANCH-STW-UB2-0005-2025 | F6: 0 | G6: 46014 | H6: 28/01- Obs: Prazo de entrega: 60 dias a contar de HOJE. 19/01- Liberado 2D. 23/12 - 3D para orçamento | I6: Labor | J6: 46058 | K6: 10236829 | L6: AR SANTOS | M6: 46118 | N6: 46118 | O6: 46120 | P6: 0 | Q6: 80813.91 | R6: =Q6/89.23 -> 905.68094 | S6: =IFERROR(VLOOKUP(L6,'Responsáveis'!$A$3:$B$140,2,FALSE),"NE") -> Rudnei | U6: SIM | V6: Em andamento | W6: Santo André
A7: VW | B7: BRBCBBB37 | C7: UB2-ST2150 | D7: GRIPPER_GEO__PNL | E7: BB37-VW-ANCH-STW-UB2-0006-2025 | F7: 0 | G7: 46014 | H7: 29/01- Processo de aquisição da matéria prima. 26/01- Aprovado por e-mail Naiara, aguardando emissão de PO. 09/01- Liberado 2D. 23/12 - 3D para orçamento | I7: Labor | J7: 46048 | L7: MECSYSTEMS | M7: 46088 | N7: 46088 | O7: 46096 | P7: 0.1 | Q7: 61482 | R7: =Q7/89.23 -> 689.02835 | S7: =IFERROR(VLOOKUP(L7,'Responsáveis'!$A$3:$B$140,2,FALSE),"NE") -> Jadiel | U7: SIM | V7: Em andamento | W7: Betim
A8: VW | B8: BRBCBBB37 | C8: UB2-ST2200 | D8: GRIPPER_GEO_PILAR | E8: BB37-VW-ANCH-STW-UB2-0007-2025 | F8: 1 | G8: 46014 | H8: 29/01 - Processo de aquisição da matéria prima. 29/01- Rev01 Grupos Modificados Grupo 03/04 - 51-38N_577941 Grupo 05/06 - 51-38N_577943 Grupo 09/10 - 51-38N_577947 Grupo 18 - 51-38N_577956 Conforme apresentação 20260127_Projeto SAGA ASUV UB2 - KIT MODIFICA - ST2245. 07/01- Liberado 2D. 23/12 - 3D para orçamento | I8: Make/Buy | J8: 46048 | K8: CONTRATO | L8: MECSYSTEMS | M8: 46088 | N8: 46088 | O8: 46096 | P8: 0.1 | Q8: 83040 | R8: =Q8/89.23 -> 930.62871 | S8: =IFERROR(VLOOKUP(L8,'Responsáveis'!$A$3:$B$140,2,FALSE),"NE") -> Jadiel | U8: SIM | V8: Em andamento | W8: Betim
A9: VW | B9: BRBCBBB37 | C9: UB2-ST2130 | D9: DOCA_GRIPPER | E9: BB37-VW-ANCH-STW-UB2-0008-2025 | F9: 1 | G9: 46014 | H9: 29/01/- Rev01 Modificação conforme apresentação 20260128_Projeto SAGA ASUV UB2 - KIT MODIFICA - ST2200 26/01- PRAZO DE ENTREGA: 35 Dias. 06/01 - Liberado 2D. 23/12- 3D para orçamento | I9: Buy | J9: 46037 | L9: TITAN | M9: 46083 | N9: 46083 | O9: 46093 | P9: 0.4 | Q9: 31520.54 | R9: =Q9/89.23 -> 353.25048 | S9: =IFERROR(VLOOKUP(L9,'Responsáveis'!$A$3:$B$140,2,FALSE),"NE") -> Rudnei | U9: SIM | V9: Em andamento
A10: VW | B10: BRBCBBB37 | C10: UB2-ST2130 | D10: DOCA_GRIPPER | E10: BB37-VW-ANCH-STW-UB2-0009-2025 | F10: 1 | G10: 46014 | H10: 29/01- Rev01 Itens modificados - 51-38N_577931_0055_05. Conforme apresentação 20260127_Projeto SAGA ASUV UB2 - KIT MODIFICA - ST220026/01- PRAZO DE ENTREGA: 35 Dias. 06/01- Liberado 2D. 23/12 - 3D para orçamento | I10: Buy | J10: 46038 | L10: TITAN | M10: 46083 | N10: 46083 | O10: 46083 | P10: 0.3 | Q10: 47818.71 | R10: =Q10/89.23 -> 535.90396 | S10: =IFERROR(VLOOKUP(L10,'Responsáveis'!$A$3:$B$140,2,FALSE),"NE") -> Rudnei | U10: SIM | V10: Em andamento
A11: VW | B11: BRBCBBB37 | C11: ST2150 | D11: DOCA PARA GRIPPER | E11: BB37-VW-ANCH-STW-UB2-00​1​0-2025 | F11: 0 | G11: 46015 | H11: 06/01 - Liberado 2D. 24/12 - 3D para orçamento | I11: Labor | J11: 46041 | L11: TITAN | M11: 46077 | N11: 46077 | O11: 46077 | P11: 0.4 | Q11: 25732 | R11: =Q11/89.23 -> 288.37835 | S11: =IFERROR(VLOOKUP(L11,'Responsáveis'!$A$3:$B$140,2,FALSE),"NE") -> Rudnei | U11: SIM | V11: Em andamento
A12: VW | B12: BRBCBBB37 | C12: ST2180 | D12: DOCA PARA GRIPPER | E12: BB37-VW-ANCH-STW-UB2-0011-2025 | F12: 0 | G12: 46015 | H12: 26/01 - Liberado a Fabricação com TITAN Cesar Marcantonio - 22/01/2026 Montagem e BM com MFG 26/01 - Entrega 35 dias após aprovação. 06/01 - Liberado 2D. 24/12 - 3D para orçamento | I12: Labor | J12: 46044 | K12: CONTRATO | L12: TITAN | M12: 46083 | N12: 46083 | O12: 46083 | P12: 0.3 | Q12: 31628.8 | R12: =Q12/89.23 -> 354.46375 | S12: =IFERROR(VLOOKUP(L12,'Responsáveis'!$A$3:$B$140,2,FALSE),"NE") -> Rudnei | U12: SIM | V12: Em andamento
A13: VW | B13: BRBCBBB37 | C13: UB2-ST2120 | D13: MESA PASSAGEM | E13: BB37-VW-ANCH-STW-UB2-0012-2025 | F13: 0 | G13: 46015 | H13: 29/01/2026 - Processo de aquisição da matéria prima. 23/01 - Liberado 2D. 24/12 - 3D para orçamento | I13: Make/Buy | J13: 46048 | K13: CONTRATO | L13: MECSYSTEMS | M13: 46083 | N13: 46083 | O13: 46096 | P13: 0.1 | Q13: 55000 | R13: =Q13/89.23 -> 616.38462 | S13: =IFERROR(VLOOKUP(L13,'Responsáveis'!$A$3:$B$140,2,FALSE),"NE") -> Jadiel | U13: SIM | V13: Em andamento | W13: Betim
A14: VW | B14: BRBCBBB37 | C14: ST2120 | D14: PALLET DE APOIO | E14: BB37-VW-ANCH-STW-UB2-0013-2025 | F14: 0 | G14: 46015 | H14: 18/02- Obs: Por favor, paralisar este processo. Item sofrerá revisão. 18/02- Obs: Alvaro solicitou o seguinte peço que suspenda a construção desta transmissão. 23/01- Liberado 2D. 24/12 - 3D para orçamento | I14: Buy | J14: 46058 | K14: 10236942 | L14: PERFECTON | M14: 46085 | N14: 46085 | P14: 0 | Q14: 71125.3 | R14: =Q14/89.23 -> 797.10075 | S14: =IFERROR(VLOOKUP(L14,'Responsáveis'!$A$3:$B$140,2,FALSE),"NE") -> Ana | U14: SIM | V14: Paralisado
A15: VW | B15: BRBCBBB37 | C15: ST2120 | D15: GRIPPER GEO | E15: BB37-VW-ANCH-STW-UB2-0014-2025 | F15: 1 | G15: 46015 | H15: 05/02-Rev01 Modificação conforme apresentação .ppt20260204_Projeto SAGA ASUV UB2 - KIT MODIFICA - ST2190 Itens acrescentados51-30D_409549 - BG01 ESTRUTURA Adicionados itens 061 e 063 (console para robô). 09/01- Liberado 2D. 24/12 - 3D para orçamento; | I15: Make/Buy | J15: 46014 | K15: CONTRATO | L15: IMECOR | M15: 46072 | N15: 46072 | O15: 46081 | P15: 1 | Q15: 25194.95 | R15: =Q15/89.23 -> 282.35963 | S15: =IFERROR(VLOOKUP(L15,'Responsáveis'!$A$3:$B$140,2,FALSE),"NE") -> Ana | U15: SIM | V15: Em andamento | W15: Santo André
A16: VW | B16: BRBCBBB37 | C16: ST2120 | D16: GRIPPER | E16: BB37-VW-ANCH-STW-UB2-0015-2025 | F16: 1 | G16: 46015 | H16: 29/01- Rev01 Itens modificados ,51-30D_409581_0041-51-30D_409581_0065 Conforme apresentação. 20260127_Projeto SAGA ASUV UB2 - KIT MODIFICA - ST219316/01- Liberado 2D. 15/01- Obs: Prazo de entrega: 45 dias após liberação dos desenhos 2D 24/12 - 3D para orçamento | I16: Make | J16: 46037 | K16: CONTRATO | L16: IMECOR | M16: 46084 | N16: 46084 | O16: 46091 | P16: 0 | Q16: 35777 | R16: =Q16/89.23 -> 400.95259 | S16: =IFERROR(VLOOKUP(L16,'Responsáveis'!$A$3:$B$140,2,FALSE),"NE") -> Ana | U16: SIM | V16: Em andamento | W16: Santo André
A17: VW | B17: BRBCBBB37 | C17: ST2150 | D17: GRIPPER BACKPANEL | E17: BB37-VW-ANCH-STW-UB2-0016-2025 | F17: 1 | G17: 46015 | H17: 06/02- Rev01 Modificação conforme apresentação .ppt 20260402_Projeto SAGA ASUV UB2 - KIT MODIFICA - ST2211 Com relação a compra dos grampos foi cancelado os grupos 08 e 12 e foi acrescentado os grupos 13 e 15. Então não tem grampos para serem comprados vão ser usado os grampos dos grupos 08 e 12 | I17: Make/Buy | J17: 46014 | K17: CONTRATO | L17: IMECOR | M17: 46072 | N17: 46072 | O17: 46081 | P17: 1 | Q17: 27630 | R17: =Q17/89.23 -> 309.64922 | S17: =IFERROR(VLOOKUP(L17,'Responsáveis'!$A$3:$B$140,2,FALSE),"NE") -> Ana | U17: SIM | V17: Em andamento | W17: Santo André
A18: VW | B18: BRBCBBB37 | C18: ST2170 | D18: GRIPPER APILLAR | E18: BB37-VW-ANCH-STW-UB2-0017-2025 | F18: 1 | G18: 46015 | H18: 05/02- Rev01 Modificação conforme apresentação .ppt 20260204_Projeto SAGA ASUV UB2 - KIT MODIFICA - ST2241Itens modificados51-30D_409553 - BG01ESTRUTURAAdicionado itens 053 e 055 (console para robô. 09/01- Liberado 2D. 24/12 - 3D para orçamento | I18: Make/Buy | J18: 46014 | K18: CONTRATO | L18: IMECOR | M18: 46072 | N18: 46072 | O18: 46081 | P18: 1 | Q18: 26637.05 | R18: =Q18/89.23 -> 298.52124 | S18: =IFERROR(VLOOKUP(L18,'Responsáveis'!$A$3:$B$140,2,FALSE),"NE") -> Ana | U18: SIM | V18: Em andamento | W18: Santo André
A19: VW | B19: BRBCBBB37 | C19: ST2170 | D19: PALLET DE APOIO | E19: BB37-VW-ANCH-STW-UB2-0019-2025 | F19: 0 | G19: 46018 | H19: 18/02- Obs: Peço que suspenda a construção desta transmissão.Assim que tiver mais informação, passarei.Item sofrerá revisão. 27/01- Liberado 2D. 27/12 - 3D para orçamento | I19: Buy | J19: 46058 | K19: 10236942 | L19: PERFECTON | M19: 46085 | N19: 46085 | P19: 0 | Q19: 89842.56 | R19: =Q19/89.23 -> 1006.865 | S19: =IFERROR(VLOOKUP(L19,'Responsáveis'!$A$3:$B$140,2,FALSE),"NE") -> Ana | U19: SIM | V19: Paralisado
A20: VW | B20: BRBCBBB37 | C20: GEO_STW_ST2520 | D20: DISPOSITIVO DE GEOMETRIA | E20: BB37-VW-ANCH-STW-UB2-0020-2025 | F20: 0 | G20: 46018 | H20: 06/01- Liberado 3D. 27/12 - 3D para orçamento | I20: Buy | J20: 46057 | K20: 10236773 | L20: PREMIUM USINAGEM | M20: 46111 | N20: 46111 | P20: 0 | Q20: 112145.22 | R20: =Q20/89.23 -> 1256.8107 | S20: =IFERROR(VLOOKUP(L20,'Responsáveis'!$A$3:$B$140,2,FALSE),"NE") -> Rudnei | U20: SIM | V20: Em andamento
A21: VW | B21: BRBCBBB37 | C21: ST2610 | D21: DISPOSITIVO DE GEOMETRIA | E21: BB37-VW-ANCH-STW-UB2-0021-2025 | F21: 0 | G21: 46019 | H21: 28/01- Obs: Aguardandon emissão de PO. 28/01- Obs: PRAZO DE ENTREGA: 60 dias a partir de hoje. 10/01 - Liberados desenhos 2D. 28/12 - 3D para orçamento | I21: Buy | J21: 46051 | K21: 10236466 | L21: PREMIUM USINAGEM | M21: 46110 | N21: 46110 | P21: 0 | Q21: 61038.45 | R21: =Q21/89.23 -> 684.05749 | S21: =IFERROR(VLOOKUP(L21,'Responsáveis'!$A$3:$B$140,2,FALSE),"NE") -> Rudnei | U21: SIM | V21: Em andamento
A22: VW | B22: BRBCBBB37 | C22: ST2620 | D22: DISPOSITIVO DE GEOMETRIA | E22: BB37-VW-ANCH-STW-UB2-0022-2025 | F22: 1 | G22: 46019 | H22: 12/02- Rev01 Modificação conforme apresentação .ppt MODIF_GEO_ST2620_260203 Acrescentado grampo28/01- Obs: Aguardandon emissão de PO. 28/01- Obs: PRAZO DE ENTREGA: 60 dias a partir de hoje. 12/01 - Liberados desenhos 2D. 28/12 - 3D para orçamento | I22: Buy | J22: 46051 | K22: 10236466 | L22: PREMIUM USINAGEM | M22: 46110 | N22: 46110 | P22: 0 | Q22: 44162.87 | R22: =Q22/89.23 -> 494.93298 | S22: =IFERROR(VLOOKUP(L22,'Responsáveis'!$A$3:$B$140,2,FALSE),"NE") -> Rudnei | U22: SIM | V22: Em andamento
A23: VW | B23: BRBCBBB37 | C23: ST2690 | D23: DISPOSITIVO DE GEOMETRIA | E23: BB37-VW-ANCH-STW-UB2-0023-2025 | F23: 1 | G23: 46019 | H23: 13/02- Obs: Reprogramação conforme planilha do SCL Diego. 10/02- Rev01 Modificação conforme apresentação .pptMODIF_GEO_ST2690_260129 29/01- Obs: prazo de entrega 40 dias. 07/01 - Liberado 2D. 28/12 - 3D para orçamento | I23: Buy | J23: 46051 | K23: 10236484 | L23: AR SANTOS | M23: 46091 | N23: 46094 | O23: 46094 | P23: 0 | Q23: 89646.78 | R23: =Q23/89.23 -> 1004.6709 | S23: =IFERROR(VLOOKUP(L23,'Responsáveis'!$A$3:$B$140,2,FALSE),"NE") -> Rudnei | U23: SIM | V23: Em andamento
A24: VW | B24: BRBCBBB37 | C24: ST2710 | D24: DISPOSITIVO DE GEOMETRIA | E24: BB37-VW-ANCH-STW-UB2-0024-2025 | F24: 0 | G24: 46019 | H24: 28/01- Obs: aguardando emissão de PO. 28/01- Obs: PRAZO DE ENTREGA: 60 dias a partir de hoje. 13/01-Liberado 2D. 28/12 - 3D para orçamento | I24: Buy | J24: 46051 | K24: 10236466 | L24: PREMIUM USINAGEM | M24: 46110 | N24: 46110 | P24: 0 | Q24: 88102.28 | R24: =Q24/89.23 -> 987.36165 | S24: =IFERROR(VLOOKUP(L24,'Responsáveis'!$A$3:$B$140,2,FALSE),"NE") -> Rudnei | U24: SIM | V24: Em andamento
A25: VW | B25: BRBCBBB37 | C25: ST2780 | D25: DISPOSITIVO DE GEOMETRIA | E25: BB37-VW-ANCH-STW-UB2-0025-2025 | F25: 0 | G25: 46019 | H25: 04/02 - "No syncplicity desenhos da base que estava pendente.... " 29/01- Obs: PRAZO DE ENTREGA: 40 dias. 16/01- Liberado 2D. 28/12 - 3D para orçamento | I25: Labor | J25: 46049 | K25: CONTRATO | L25: AR SANTOS | M25: 46095 | N25: 46095 | P25: 0 | Q25: 96924.74 | R25: =Q25/89.23 -> 1086.2349 | S25: =IFERROR(VLOOKUP(L25,'Responsáveis'!$A$3:$B$140,2,FALSE),"NE") -> Rudnei | U25: SIM | V25: Em andamento
A26: VW | B26: BRBCBBB37 | C26: ST2645 | D26: DISPOSITIVO DE RESPOT | E26: BB37-VW-ANCH-STW-UB2-0026-2025 | F26: 0 | G26: 46019 | H26: 28/01- Obs: Aguardandon emissão de PO. 28/01- Obs: PRAZO DE ENTREGA: 60 dias a partir de hoje 07/01- Liberado 2D. 28/12 - 3D para orçamento | I26: Buy | J26: 46051 | K26: 10236466 | L26: PREMIUM USINAGEM | M26: 46110 | N26: 46110 | P26: 0 | Q26: 40190.2 | R26: =Q26/89.23 -> 450.4113 | S26: =IFERROR(VLOOKUP(L26,'Responsáveis'!$A$3:$B$140,2,FALSE),"NE") -> Rudnei | U26: SIM | V26: Em andamento
A27: VW | B27: BRBCBBB37 | C27: ST2720 | D27: DISPOSITIVO DE RESPOT | E27: BB37-VW-ANCH-STW-UB2-0027-2025 | F27: 0 | G27: 46019 | H27: 13/02- Obs: Reprogramação conforme planilha do SCL Diego. | I27: Buy | J27: 46057 | K27: 10236773 | L27: PREMIUM USINAGEM | M27: 46111 | N27: 46132 | P27: 0 | Q27: 52555.14 | R27: =Q27/89.23 -> 588.98509 | S27: =IFERROR(VLOOKUP(L27,'Responsáveis'!$A$3:$B$140,2,FALSE),"NE") -> Rudnei | U27: SIM | V27: Em andamento
A28: VW | B28: BRBCBBB37 | C28: ST2800 | D28: DISPOSITIVO DE RESPOT | E28: BB37-VW-ANCH-STW-UB2-0028-2025 | F28: 0 | G28: 46019 | H28: 13/02- Obs: Reprogramação conforme planilha do SCL Diego. 30/01- PRAZO DE ENTREGA: 60 dias. 13/01- Liberado 2D. 28/12 - 3D para orçamento | I28: Buy | J28: 46057 | K28: 10236773 | L28: PREMIUM USINAGEM | M28: 46114 | N28: 46132 | P28: 0 | Q28: 63500 | R28: =Q28/89.23 -> 711.64407 | S28: =IFERROR(VLOOKUP(L28,'Responsáveis'!$A$3:$B$140,2,FALSE),"NE") -> Rudnei | U28: SIM | V28: Em andamento
A29: VW | B29: BRBCBBB37 | C29: ST2640 | D29: GRIPPER | E29: BB37-VW-ANCH-STW-UB2-0029-2025 | F29: 1 | G29: 46019 | H29: 23/01 - Rev01 Modificação conforme apresentação“MODIF_GARRA_PINCA_ST2640_260121” , acrescentado comercial SZKD40 BR4 A18 T12X4015/01- Liberado 2D. 28/12 - 3D para orçamento | I29: Make/Buy | J29: 46017 | K29: CONTRATO | L29: IMECOR | M29: 46082 | N29: 46082 | O29: 46089 | P29: 0.1 | Q29: 23030 | R29: =Q29/89.23 -> 258.09705 | S29: =IFERROR(VLOOKUP(L29,'Responsáveis'!$A$3:$B$140,2,FALSE),"NE") -> Ana | U29: SIM | V29: Em andamento | W29: Santo André
A30: VW | B30: BRBCBBB37 | C30: ST2830 | D30: GRIPPER | E30: BB37-VW-ANCH-STW-UB2-0030-2025 | F30: 1 | G30: 46019 | H30: 29/01- Rev01 Modificação conforme apresentação ERA DIVENTA-GRIPPER_ST2830-20260128. 28/01- Obs: A garra desta transmissão teve uma modificação. No link abaixo esta o kit modifica e ela completa para troca na rede. 15/01- Liberado 2D. 28/12 - 3D para orçamento | I30: Make/Buy | J30: 46019 | K30: CONTRATO | L30: IMECOR | M30: 46082 | N30: 46082 | O30: 46089 | P30: 0.1 | Q30: 15740.55 | R30: =Q30/89.23 -> 176.40424 | S30: =IFERROR(VLOOKUP(L30,'Responsáveis'!$A$3:$B$140,2,FALSE),"NE") -> Ana | U30: SIM | V30: Em andamento | W30: Santo André
A31: VW | B31: BRBCBBB37 | C31: ST2790 | D31: GRIPPER | E31: BB37-VW-ANCH-STW-UB2-0031-2025 | F31: 0 | G31: 46019 | H31: 22/01- Liberado 2D. 16/12- Obs: Prazo de entrega: 45 dias após liberação dos desenhos 2D. 28/12 - 3D para orçamento | I31: Make/Buy | J31: 46371 | K31: CONTRATO | L31: IMECOR | M31: 46089 | N31: 46089 | O31: 46096 | P31: 0.1 | Q31: 21345.55 | R31: =Q31/89.23 -> 239.21943 | S31: =IFERROR(VLOOKUP(L31,'Responsáveis'!$A$3:$B$140,2,FALSE),"NE") -> Ana | U31: SIM | V31: Em andamento | W31: Santo André
A32: VW | B32: BRBCBBB37 | C32: ST2770 | D32: GRIPPER | E32: BB37-VW-ANCH-STW-UB2-0032-2025 | F32: 0 | G32: 46019 | H32: 15/01- Prazo de entrega: 45 dias após liberação dos desenhos 2D. 28/12 - 3D para orçamento. | I32: Make/Buy | J32: 46371 | K32: CONTRATO | L32: IMECOR | P32: 0 | Q32: 22862.7 | R32: =Q32/89.23 -> 256.22212 | S32: =IFERROR(VLOOKUP(L32,'Responsáveis'!$A$3:$B$140,2,FALSE),"NE") -> Ana | U32: SIM | V32: Em andamento | W32: Santo André
A33: VW | B33: BRBCBBB37 | C33: ST2750 | D33: GRIPPER | E33: BB37-VW-ANCH-STW-UB2-0033-2025 | F33: 1 | G33: 46019 | H33: 30/01- Rev01 Modificação conforme apresentação .ppt ERA DIVENTA-GRIPPER_ST2750-20260130. 30/01- Obs: A garra desta transmissão teve uma modificação. No link abaixo esta o kit modifica e ela completa para troca na rede. 10/01 - Liberados desenhos 2D. 28/12 - 3D para orçamento | I33: Make/Buy | J33: 46019 | K33: CONTRATO | L33: IMECOR | M33: 46072 | N33: 46072 | O33: 46081 | P33: 0.5 | Q33: 27899.6 | R33: =Q33/89.23 -> 312.67063 | S33: =IFERROR(VLOOKUP(L33,'Responsáveis'!$A$3:$B$140,2,FALSE),"NE") -> Ana | U33: SIM | V33: Em andamento | W33: Santo André
A34: VW | B34: BRBCBBB37 | C34: ST2730 | D34: GRIPPER | E34: BB37-VW-ANCH-STW-UB2-0034-2025 | F34: 1 | G34: 46019 | H34: 22/01- Rev01 Modificação conforme apresentação .pptKIT_MOD_GARRA_ST2730_REV01 28/12 - 3D para orçamento | I34: Make/Buy | J34: 46017 | K34: CONTRATO | L34: IMECOR | M34: 46082 | N34: 46082 | O34: 46089 | P34: 0.1 | Q34: 27471.15 | R34: =Q34/89.23 -> 307.86899 | S34: =IFERROR(VLOOKUP(L34,'Responsáveis'!$A$3:$B$140,2,FALSE),"NE") -> Ana | U34: SIM | V34: Em andamento | W34: Santo André
A35: VW | B35: BRBCBBB37 | C35: ST2710 | D35: GRIPPER | E35: BB37-VW-ANCH-STW-UB2-0035-2025 | F35: 0 | G35: 46019 | H35: 16/01- Liberado 2D. 15/01- Prazo de entrega: 45 dias após liberação dos desenhos 2D. 28/12 - 3D para orçamento | I35: Make | J35: 46037 | K35: CONTRATO | L35: IMECOR | M35: 46084 | N35: 46084 | O35: 46091 | P35: 1 | Q35: 44996.75 | R35: =Q35/89.23 -> 504.27827 | S35: =IFERROR(VLOOKUP(L35,'Responsáveis'!$A$3:$B$140,2,FALSE),"NE") -> Ana | U35: SIM | V35: Em andamento | W35: Santo André
A36: VW | B36: BRBCBBB37 | C36: ST2700 | D36: GRIPPER | E36: BB37-VW-ANCH-STW-UB2-0036-2025 | F36: 0 | G36: 46019 | H36: 23/12- 3D PARA ORÇAMENTO | I36: Em definição | R36: =Q36/89.23 -> 0 | S36: =IFERROR(VLOOKUP(L36,'Responsáveis'!$A$3:$B$140,2,FALSE),"NE") -> NE | U36: SIM | V36: Em planejamento
A37: VW | B37: BRBCBBB37 | C37: ST2650 | D37: GRIPPER | E37: BB37-VW-ANCH-STW-UB2-0037-2025 | F37: 1 | G37: 46019 | H37: 22/01- Rev01 Modificação conforme indicado na apresentação .pptMODIF_GARRA_PINCA_ST2650_260121 10/01- Liberado 2D. 28/12 - 3D para orçamento | I37: Make | J37: 46030 | K37: CONTRATO | L37: IMECOR | M37: 46072 | N37: 46072 | O37: 46081 | P37: 0.5 | Q37: 23468 | R37: =Q37/89.23 -> 263.00572 | S37: =IFERROR(VLOOKUP(L37,'Responsáveis'!$A$3:$B$140,2,FALSE),"NE") -> Ana | U37: SIM | V37: Em andamento | W37: Santo André
A38: VW | B38: BRBCBBB37 | C38: ST2630 | D38: GRIPPER | E38: BB37-VW-ANCH-STW-UB2-0038-2025 | F38: 0 | G38: 46019 | H38: 15/01- Liberado 2D. 28/12 - 3D para orçamento | I38: Make/Buy | J38: 46030 | K38: CONTRATO | L38: IMECOR | M38: 46072 | N38: 46072 | O38: 46081 | P38: 1 | Q38: 33020.1 | R38: =Q38/89.23 -> 370.05604 | S38: =IFERROR(VLOOKUP(L38,'Responsáveis'!$A$3:$B$140,2,FALSE),"NE") -> Ana | U38: SIM | V38: Em andamento | W38: Santo André
A39: VW | B39: BRBCBBB37 | C39: ST2620 | D39: GRIPPER | E39: BB37-VW-ANCH-STW-UB2-0039-2025 | F39: 2 | G39: 46019 | H39: 11/02- Rev02 Modificado conforme apresentação .ppt MODIF_GARRA_PINCA_ST2620_260203, atualizado pino index 28/01- Rev01 Modificado conforme apresentação .pptMODIF_GARRA_PINCA_ST2620_260127, acrescentado comerciais dos novos grupos 09/01- Liberado 2D. 28/12 - 3D para orçamento | I39: Make/Buy | J39: 46030 | K39: CONTRATO | L39: IMECOR | M39: 46072 | N39: 46072 | O39: 46081 | P39: 0.5 | Q39: 33824.75 | R39: =Q39/89.23 -> 379.07374 | S39: =IFERROR(VLOOKUP(L39,'Responsáveis'!$A$3:$B$140,2,FALSE),"NE") -> Ana | U39: SIM | V39: Em andamento | W39: Santo André
A40: VW | B40: BRBCBBB37 | C40: ST2600 | D40: GRIPPER | E40: BB37-VW-ANCH-STW-UB2-0040-2025 | F40: 1 | G40: 46019 | H40: 10/02-Rev01 Modificação conforme apresentação .ppt MODIF_GRIPPER_ST2600_260203 09/01- Liberado 2D. 28/12 - 3D para orçamento | I40: Make/Buy | J40: 46032 | K40: CONTRATO | L40: IMECOR | M40: 46072 | N40: 46072 | O40: 46081 | P40: 0.5 | Q40: 21992.5 | R40: =Q40/89.23 -> 246.4698 | S40: =IFERROR(VLOOKUP(L40,'Responsáveis'!$A$3:$B$140,2,FALSE),"NE") -> Ana | U40: SIM | V40: Em andamento | W40: Santo André
...

Sheet BKP de Follow-up
A1: FOLLOW-UP COMAU DO BRASIL | G1: MAKE | H1: =COUNTIFS(I3:I96, "make", V3:V96, "Em andamento") -> 0 | I1: BUY | J1: =COUNTIFS(I3:I96, "BUY", V3:V96, "Em andamento") -> 0 | K1: MAKE / BUY | L1: =COUNTIFS(I3:I96, "make/buy", V3:V96, "Em andamento") -> 0 | M1: EM DEFINIÇÃO | N1: =COUNTIFS(I3:I96, "em definição") -> 1 | O1: TOTAL | P1: =H1+J1+L1+N1 -> 1
A2: Cliente | B2: Projeto WBS | C2: Linha / OP | D2: Descrição | E2: Transmissão / Eventual | F2: Rev. | G2: Data da criação | H2: Observação | I2: Make / Buy | J2: Data de inicio | K2: Pedido de compra | L2: Fornecedor | M2: Data entrega Fornecedor | N2: Data entrega final - MFG | O2: Reprogramação | P2: Status Geral % | Q2: Valor total | R2: Qtd Hr | S2: Resp.Follow-up | T2: Nota Fiscal | U2: Comercial | V2: Status
A3: RENAULT | B3: BRBCBBA96 | C3: DBL/UAR09 | D3: MANIPULADOR | E3: BA96_DBL CUST 1312-0020-2024 | F3: 1 | G3: 45793 | H3: 02/12/25 - CANCELAMENTO VIA E-MAIL | I3: Cancelado | R3: =Q3/89.23 -> 0 | S3: =IFERROR(VLOOKUP(L3,'Responsáveis'!$A$3:$B$136,2,FALSE),"NE") -> NE | U3: SIM | V3: Cancelado
A4: VW | B4: BRBCBBB37 | C4: UNTERBAU | D4: BASES ROBOS | E4: BB37-VW-ANCH-STW-UB2-0001-2025 | F4: 1 | G4: 45978 | H4: 18/12/2025 - 3 em desempeno e 7 em usinagem. 09/12/2025 - Preparação da matéria prima em andamento. 02/12- revisão da transmissão ficando apenas as 10bases de 975, conforme negociado por compras 28/11- Rev01 Cancelado a construção das bases 11-39D 20819-5 e 11-39D 20819-6 e modificado a qtd da base 11-39D 20819-4 era 14 mudou para 10. | I4: Buy | J4: 45988 | K4: 10233669 | L4: MEC.IN SERVICE | M4: 46013 | N4: 46013 | O4: 46014 | P4: 1 | Q4: 99332.4 | R4: =Q4/89.23 -> 1113.2175 | S4: =IFERROR(VLOOKUP(L4,'Responsáveis'!$A$3:$B$136,2,FALSE),"NE") -> Jadiel | T4: 13752 | U4: NÃO | V4: Concluído
A5: STL/PWT | B5: BRBCABA16 | C5: WP0003 | D5: PCT 01 CJ FREIO | E5: EV0806 | F5: 0 | G5: 45922 | H5: 07/11 - Em processo de usinagem e acabamento, entregas sendo realizadas parciais. 24/10 - Fornecedor irá alinhar novas datas de entrega com Gesualdo nesta data. 18/10 - Em processo de usinagem 14/10 - Iniciou processo de usinagem nesta data. OS 328 | I5: Make/Buy | J5: 45923 | K5: CONTRATO | L5: WR INDUSTRIA | M5: 45985 | N5: 45953 | O5: 45989 | P5: 1 | Q5: 86853.56 | R5: =Q5/89.23 -> 973.36725 | S5: =IFERROR(VLOOKUP(L5,'Responsáveis'!$A$3:$B$136,2,FALSE),"NE") -> Jadiel | U5: NÃO | V5: Concluído | W5: Betim
A6: STL/PWT | B6: BRBCABA16 | C6: PACOTE 02 | D6: PALLET CONJ. FREIO | E6: EV0807 | F6: 0 | G6: 45922 | H6: 07/11 - Em processo de usinagem e acabamento, entregas sendo realizadas parciais. 24/10 - Fornecedor irá alinhar novas datas de entrega com Gesualdo nesta data. 18/10 - Em processo de usinagem e tratamento térmico 14/10 - Vai iniciar processo de usinagem em terceiro 15/10. OS 329 | I6: Make/Buy | J6: 45922 | K6: CONTRATO | L6: WR INDUSTRIA | M6: 45985 | N6: 45985 | O6: 45989 | P6: 1 | Q6: 89192.54 | R6: =Q6/89.23 -> 999.58019 | S6: =IFERROR(VLOOKUP(L6,'Responsáveis'!$A$3:$B$136,2,FALSE),"NE") -> Jadiel | U6: NÃO | V6: Concluído | W6: Betim
A7: STL/PWT | B7: BRBCABA16 | C7: PACOTE 03 | D7: PALLET CONJ. FREIO | E7: EV0808 | F7: 0 | G7: 45922 | H7: 07/11 - Em processo de usinagem e acabamento, entregas sendo realizadas parciais. 24/10 - Fornecedor irá alinhar novas datas de entrega com Gesualdo nesta data. 18/10 - Em processo de usinagem e tratamento térmico 14/10 - Peças pré-usinadas retorna do tratamento térmico hoje, restante irá iniciar processo de usinagem 15/10. OS 330 | I7: Make/Buy | J7: 45922 | K7: CONTRATO | L7: WR INDUSTRIA | M7: 45985 | N7: 45985 | O7: 45989 | P7: 1 | Q7: 92235.64 | R7: =Q7/89.23 -> 1033.6842 | S7: =IFERROR(VLOOKUP(L7,'Responsáveis'!$A$3:$B$136,2,FALSE),"NE") -> Jadiel | U7: NÃO | V7: Concluído | W7: Betim
A8: STL/PWT | B8: BRBCABA16 | C8: PACOTE 04 | D8: PALLET CONJ. FREIO | E8: EV0809 | F8: 0 | G8: 45922 | H8: 07/11 - Em processo de usinagem e acabamento, entregas sendo realizadas parciais. 24/10 - Fornecedor irá alinhar novas datas de entrega com Gesualdo nesta data. 18/10 - Em processo de usinagem e tratamento térmico 14/10 - Em processo de usinagem, peça de latão pronta. OS 331 | I8: Make/Buy | J8: 45922 | K8: CONTRATO | L8: WR INDUSTRIA | M8: 45985 | N8: 45985 | O8: 45989 | P8: 1 | Q8: 68413.85 | R8: =Q8/89.23 -> 766.71355 | S8: =IFERROR(VLOOKUP(L8,'Responsáveis'!$A$3:$B$136,2,FALSE),"NE") -> Jadiel | U8: NÃO | V8: Concluído | W8: Betim
A9: STL/FIAT | B9: BRBCABA16 | C9: OP.10/OP.20 | D9: DIVERSOS | E9: EV0845 | F9: 0 | G9: 45967 | H9: 05/12/2025 - Será entregue hoje. 27/11/2025 - Em processo de tratamento superficial. | I9: Make/Buy | J9: 45967 | K9: CONTRATO | L9: METALURGICA GRANATO | M9: 45988 | N9: 45988 | O9: 45996 | P9: 1 | Q9: 1569.08 | R9: =Q9/89.23 -> 17.584669 | S9: =IFERROR(VLOOKUP(L9,'Responsáveis'!$A$3:$B$136,2,FALSE),"NE") -> jadiel | T9: 34381 | U9: NÃO | V9: Concluído | W9: Betim
A10: PSA | B10: BRBCBBB21 | C10: OP28 | D10: Construção Suportes | E10: EV0883 | F10: 0 | G10: 45938 | H10: 11/11/25 - Fornecedor com as peças finalizadas irá acionar o time de qualidade Comau para realizar a liberação embalar e nos enviar; 04/11/25 - Fornecedor em processo de usinagem, peças em tratamento de zinco, peças de corte e dobra nao foram comprada pelo time de compras Madi, a mesmo esta sendo adquirido hoje para poder chegar amanhã e realizar a dobra e depois o tratamento de zinco. 27/10/25 - Fornecedor em processo de usinagem de 2 peças para adiantar o processo e depois a entrega do restante; | I10: Make/Buy | J10: 45943 | K10: CONTRATO | L10: MADI | M10: 45965 | N10: 45968 | O10: 45973 | P10: 1 | Q10: 6880.5 | R10: =Q10/89.23 -> 77.109716 | S10: =IFERROR(VLOOKUP(L10,'Responsáveis'!$A$3:$B$136,2,FALSE),"NE") -> Rudnei | T10: 7743 | U10: NÃO | V10: Concluído
A11: STL/PWT | B11: BRBCABA21 | C11: OP. 28 | D11: Montagem gravitacionais | E11: EV0894 | F11: 0 | G11: 45940 | H11: 04/11/2025 - Processo de calandra iniciando | I11: Make/Buy | J11: 45945 | K11: CONTRATO | L11: AMX | M11: 45971 | N11: 45971 | O11: 45971 | P11: 1 | Q11: 13400 | R11: =Q11/89.23 -> 150.17371 | S11: =IFERROR(VLOOKUP(L11,'Responsáveis'!$A$3:$B$136,2,FALSE),"NE") -> Ana | U11: NÃO | V11: Concluído
A12: ROBOTICA | B12: - | C12: - | D12: ACOPLAMENTO | E12: EV0906 | F12: 0 | G12: 45943 | H12: 09/12/2025 - Enviado para retrabalho. 07/11 - Aguardando envio do acoplamento para inicio do processo de retrabalho. 28/10 - Aguardando envio do acoplamento para inicio do processo de retrabalho. 23/10 - Aguardando envio do acoplamento para inicio do processo de retrabalho. | I12: Make/Buy | J12: 45944 | K12: CONTRATO | L12: WR INDUSTRIA | M12: 46010 | N12: 46010 | O12: 46010 | P12: 1 | Q12: 1132 | R12: =Q12/89.23 -> 12.686316 | S12: =IFERROR(VLOOKUP(L12,'Responsáveis'!$A$3:$B$136,2,FALSE),"NE") -> Jadiel | U12: NÃO | V12: Concluído | W12: Betim
A13: STL/PWT | B13: BRBCABA21 | C13: OP.28 | D13: CABEÇOTE | E13: EV0907 | F13: 0 | G13: 45943 | H13: 24/11/2025 - 1ª paltaforma ficará pronta na pintura amanhã 25/11/2025, a 2ª está indo para pintura hoje 24/11/2025. 07/11 - Em processo de caderaria, falta soldar e pintar. 28/10 - Material comprado, previsão de entrega 29/10. 23/10 - Em processo de compra de material OS 367 | I13: Make/Buy | J13: 45950 | K13: CONTRATO | L13: WR INDUSTRIA | M13: 45975 | N13: 45975 | O13: 45988 | P13: 1 | Q13: 25271.52 | R13: =Q13/89.23 -> 283.21775 | S13: =IFERROR(VLOOKUP(L13,'Responsáveis'!$A$3:$B$136,2,FALSE),"NE") -> Jadiel | U13: NÃO | V13: Concluído | W13: Betim
A14: PSA | B14: BRBCBBB21 | C14: 32 | D14: CABEÇOTE | E14: EV0934 | F14: 0 | G14: 45947 | H14: 07/11 - Em processo de usinagem, previsão de antecipação de entrega para 14/11. 28/10 - Em processo de compra de material e corte de matéria prima interno OS 372 | I14: Make/Buy | J14: 45947 | K14: CONTRATO | L14: WR INDUSTRIA | M14: 45983 | N14: 45983 | O14: 45983 | P14: 1 | Q14: 5128 | R14: =Q14/89.23 -> 57.469461 | S14: =IFERROR(VLOOKUP(L14,'Responsáveis'!$A$3:$B$136,2,FALSE),"NE") -> Jadiel | U14: NÃO | V14: Concluído | W14: Betim
A15: PSA | B15: BRBCBBB21 | C15: OP228 | D15: REAÇÃO PISTÃO | E15: EV0935 | F15: 0 | G15: 45947 | H15: 10/11/2025 - Chapa enviada para anodizar, previsto para amanhã, hoje será feito entraga parcial. 04/11/2025 - Estrutura enghelego já disponível, início da usinagem. 29/10 - fica registrado que os itens 19 ao 26 e 41 e 42 (itens comerciais) do conjunto WLCUG-00001N2152, estão excluso do fornecimento. | I15: Make/Buy | J15: 45954 | K15: CONTRATO | L15: AMX | M15: 45973 | N15: 45973 | O15: 45973 | P15: 1 | Q15: 34800 | R15: =Q15/89.23 -> 390.00336 | S15: =IFERROR(VLOOKUP(L15,'Responsáveis'!$A$3:$B$136,2,FALSE),"NE") -> Ana | U15: NÃO | V15: Concluído
A16: PSA | B16: BRBCBBB21 | C16: - | D16: TRECHO DE TRANSPORTES | E16: EV0940 | F16: 0 | G16: 45950 | H16: 27/11/2025 - Será entregue hoje até as 16 horas. 04/11/2025 - Preparação da matéria prima. | I16: Make/Buy | J16: 45952 | K16: CONTRATO | L16: AMX | M16: 45987 | N16: 45993 | O16: 45988 | P16: 1 | Q16: 24800 | R16: =Q16/89.23 -> 277.93343 | S16: =IFERROR(VLOOKUP(L16,'Responsáveis'!$A$3:$B$136,2,FALSE),"NE") -> Ana | U16: NÃO | V16: Concluído | W16: Betim
A17: RENAULT | B17: BRBCBBB29 | C17: - | D17: Dressador - Fiat | E17: EV0942 | F17: 0 | G17: 45951 | H17: 04/11/2025 - Preparação da matéria prima. | I17: Make/Buy | J17: 45957 | K17: CONTRATO | L17: AMX | M17: 45979 | N17: 45979 | O17: 45982 | P17: 1 | Q17: 55000 | R17: =Q17/89.23 -> 616.38462 | S17: =IFERROR(VLOOKUP(L17,'Responsáveis'!$A$3:$B$136,2,FALSE),"NE") -> Ana | U17: NÃO | V17: Concluído | W17: Betim
A18: STL/PWT | B18: BRBCABA16 | C18: OP30 | D18: BARRA ESTABILIZADORA | E18: EV0957 | F18: 0 | G18: 45954 | H18: 07/11/2025 - Será entregue amanhã 08/11/2025 devido a retoques na pintura. 07/11/2025 - Será entregue hoje as 15 horas 4/11/2025 - Processo de usinagem em andamento. | I18: Make/Buy | J18: 45954 | K18: CONTRATO | L18: AMX | M18: 45968 | N18: 45968 | O18: 45970 | P18: 1 | Q18: 8350 | R18: =Q18/89.23 -> 93.578393 | S18: =IFERROR(VLOOKUP(L18,'Responsáveis'!$A$3:$B$136,2,FALSE),"NE") -> Ana | U18: NÃO | V18: Concluído
A19: STL/PWT | B19: BRBCABA19 | C19: - | D19: FABRICAÇÃO DE PEÇAS USINADAS | E19: EV0962 | F19: 0 | G19: 45954 | H19: 08/11 - Enviado para MG nesta data 03/11 - Será enviado dia 06/11 | I19: Make/Buy | J19: 45958 | K19: CONTRATO | L19: IMECOR | M19: 45972 | N19: 45974 | O19: 45972 | P19: 1 | Q19: 13650 | R19: =Q19/89.23 -> 152.97546 | S19: =IFERROR(VLOOKUP(L19,'Responsáveis'!$A$3:$B$136,2,FALSE),"NE") -> Ana | U19: NÃO | V19: Concluído
A20: STL/PWT | B20: BRBCABA16 | C20: OP.20/OP.30 | D20: RETOOLING SUSPENSÃO | E20: EV0963 | F20: 0 | G20: 45957 | H20: 11/11/2025 - Usinagem em andamento. | I20: Make/Buy | J20: 45958 | K20: CONTRATO | L20: MECSYSTEMS | M20: 45976 | N20: 45983 | O20: 45976 | P20: 1 | Q20: 5040.26 | R20: =Q20/89.23 -> 56.486159 | S20: =IFERROR(VLOOKUP(L20,'Responsáveis'!$A$3:$B$136,2,FALSE),"NE") -> Jadiel | U20: NÃO | V20: Concluído
A21: STL/FIAT | B21: BRBCBBB13 | C21: AUA 040 | D21: KIT APOIO | E21: EV0980 | F21: 0 | G21: 45959 | H21: 07/11 - Enviado para MG nesta data | I21: Make/Buy | J21: 45961 | K21: CONTRATO | L21: IMECOR | M21: 45973 | N21: 45973 | O21: 45973 | P21: 1 | Q21: 11060 | R21: =Q21/89.23 -> 123.94934 | S21: =IFERROR(VLOOKUP(L21,'Responsáveis'!$A$3:$B$136,2,FALSE),"NE") -> Ana | U21: NÃO | V21: Concluído
A22: STL/PWT | B22: BRBCABA19 | C22: - | D22: DIVERSOS | E22: EV0981 | F22: 0 | G22: 45951 | H22: 24/11/25 - Fornecedor acionou o time da qualidade Comau para realizar a liberação da adicional; 11/11/25 - Itens já foram solicitados por compras, aguardando chegar para entregar juntamente com a transmissão FAM B-0111; 04/11/25 - Itens já foram solicitados por compras, aguardando chegar para entregar juntamente com a transmissão FAM B-0111; | I22: Make/Buy | J22: 45957 | K22: CONTRATO | L22: MADI | M22: 45962 | N22: 45962 | O22: 45985 | P22: 1 | Q22: 2970 | R22: =Q22/89.23 -> 33.28477 | S22: =IFERROR(VLOOKUP(L22,'Responsáveis'!$A$3:$B$136,2,FALSE),"NE") -> Rudnei | T22: 7764 | U22: NÃO | V22: Concluído | W22: Betim
A23: STL/PWT | B23: BRBCABA19 | C23: OP.80/250 | D23: SENSORIAMENTO | E23: EV0988 | F23: 0 | G23: 45960 | H23: 26/11/2025 - Será entregue hoje no fim do dia. 25/11 - Será entregue hoje as 15 horas. 12/11/2025 - Preparação da matéria prima em andamento. | I23: Make/Buy | J23: 45968 | K23: CONTRATO | L23: EINTEGRA | M23: 45978 | N23: 45978 | O23: 45987 | P23: 1 | Q23: 1455 | R23: =Q23/89.23 -> 16.306175 | S23: =IFERROR(VLOOKUP(L23,'Responsáveis'!$A$3:$B$136,2,FALSE),"NE") -> jadiel | U23: NÃO | V23: Concluído
A24: STL/PWT | B24: BRBCABA20 | C24: - | D24: Gancho Front Cradle | E24: EV0989 | F24: 0 | G24: 45960 | H24: 06/11 - Enviado para MG nesta data | I24: Make/Buy | J24: 45964 | K24: CONTRATO | L24: IMECOR | M24: 45969 | N24: 45969 | O24: 45972 | P24: 1 | Q24: 4250 | R24: =Q24/89.23 -> 47.629721 | S24: =IFERROR(VLOOKUP(L24,'Responsáveis'!$A$3:$B$136,2,FALSE),"NE") -> Ana | U24: NÃO | V24: Concluído
A25: STL/FIAT | B25: BRBCBBB26 | C25: AUA120 / SCA250 | D25: PROTEÇÃO POLICARBONATO | E25: EV0990 | F25: 0 | G25: 45960 | I25: Make/Buy | J25: 45965 | K25: CONTRATO | L25: IMECOR | M25: 46017 | N25: 46018 | O25: 46017 | P25: 1 | Q25: 11280 | R25: =Q25/89.23 -> 126.41488 | S25: =IFERROR(VLOOKUP(L25,'Responsáveis'!$A$3:$B$136,2,FALSE),"NE") -> Ana | U25: NÃO | V25: Concluído | W25: Betim
A26: STL/FIAT | B26: BRBCBBB26 | C26: DORSAL 1 | D26: SUPORTE PARA CABOS | E26: EV0991 | F26: 0 | G26: 45960 | H26: 25/11 - Enviado para MG nesta data | I26: Make/Buy | J26: 45962 | K26: CONTRATO | L26: IMECOR | M26: 45989 | N26: 45992 | O26: 45990 | P26: 1 | Q26: 2400 | R26: =Q26/89.23 -> 26.896784 | S26: =IFERROR(VLOOKUP(L26,'Responsáveis'!$A$3:$B$136,2,FALSE),"NE") -> Ana | U26: NÃO | V26: Concluído
A27: STL/PWT | B27: BRBCABA21 | C27: - | D27: CONJUNTO DE ITENS | E27: EV0992 | F27: 0 | G27: 45961 | H27: 02/12/2025 - Peças em processo de zincagem, previsão de entrega as 15 horas. 12/11/2025 - Caldeiraria e usinagem em andamento. 05/11/2025 - Gestão dos desenhos e matéria prima em andamento. | I27: Make/Buy | J27: 45962 | K27: CONTRATO | L27: EINTEGRA | M27: 45985 | N27: 45990 | O27: 45999 | P27: 1 | Q27: 22500 | R27: =Q27/89.23 -> 252.15735 | S27: =IFERROR(VLOOKUP(L27,'Responsáveis'!$A$3:$B$136,2,FALSE),"NE") -> jadiel | U27: NÃO | V27: Concluído | W27: Betim
A28: STL/PWT | B28: BRBCABA20 | C28: OP.040 | D28: SETUP APERTADEIRA | E28: EV0995 | F28: 0 | G28: 45964 | I28: Make/Buy | J28: 45964 | K28: CONTRATO | L28: AMX | M28: 45972 | N28: 45973 | O28: 45972 | P28: 1 | Q28: 6350 | R28: =Q28/89.23 -> 71.164407 | S28: =IFERROR(VLOOKUP(L28,'Responsáveis'!$A$3:$B$136,2,FALSE),"NE") -> Ana | U28: NÃO | V28: Concluído
A29: STL/PWT | B29: BRBCABA16 | C29: OP.141 | D29: retrabalho bloco reacao | E29: EV0998 | F29: 0 | G29: 45965 | I29: Make | J29: 45965 | K29: CONTRATO | L29: MANUFACTURING | M29: 45966 | N29: 45969 | O29: 45966 | P29: 1 | Q29: 1277.55 | R29: =Q29/89.23 -> 14.317494 | S29: =IFERROR(VLOOKUP(L29,'Responsáveis'!$A$3:$B$136,2,FALSE),"NE") -> Ana | U29: NÃO | V29: Concluído
A30: GM | B30: BRBCBBA98 | C30: CTE001 | D30: CHAPAS | E30: EV1006 | F30: 0 | G30: 45966 | H30: 07/11 - Enviado nesta data | I30: Make/Buy | J30: 45966 | K30: CONTRATO | L30: IMECOR | M30: 45972 | N30: 45972 | O30: 45972 | P30: 1 | Q30: 16800 | R30: =Q30/89.23 -> 188.27749 | S30: =IFERROR(VLOOKUP(L30,'Responsáveis'!$A$3:$B$136,2,FALSE),"NE") -> Ana | U30: NÃO | V30: Concluído
A31: STL/PWT | B31: BRBCABA21 | C31: OP.560 | D31: DIVERSOS | E31: EV1008 | F31: 0 | G31: 45966 | H31: 08/11 - Enviado para MG nesta data | I31: Make/Buy | J31: 45967 | K31: CONTRATO | L31: IMECOR | M31: 45972 | N31: 45972 | O31: 45974 | P31: 1 | Q31: 2660 | R31: =Q31/89.23 -> 29.810602 | S31: =IFERROR(VLOOKUP(L31,'Responsáveis'!$A$3:$B$136,2,FALSE),"NE") -> Ana | U31: NÃO | V31: Concluído
A32: GM | B32: BRBCBBA98 | C32: YD120 | D32: MANIPULADOR | E32: EV1009 | F32: 0 | G32: 45966 | H32: 07/11 - Enviado para MG nesta data | I32: Make/Buy | J32: 45967 | K32: CONTRATO | L32: IMECOR | M32: 45972 | N32: 45972 | O32: 45973 | P32: 1 | Q32: 1420 | R32: =Q32/89.23 -> 15.91393 | S32: =IFERROR(VLOOKUP(L32,'Responsáveis'!$A$3:$B$136,2,FALSE),"NE") -> Ana | U32: NÃO | V32: Concluído
A33: JEEP | B33: BRBRRBA18 | C33: FXA060 | D33: APOIO DE TESTE | E33: EV1010 | F33: 0 | G33: 45959 | H33: 08/11 - Enviado para MG nesta data | I33: Make/Buy | J33: 45967 | K33: CONTRATO | L33: IMECOR | M33: 45969 | N33: 45969 | O33: 45974 | P33: 1 | Q33: 4460.4 | R33: =Q33/89.23 -> 49.987672 | S33: =IFERROR(VLOOKUP(L33,'Responsáveis'!$A$3:$B$136,2,FALSE),"NE") -> Ana | U33: NÃO | V33: Concluído
A34: STL/FIAT | B34: BRBCABA16 | C34: OP.30 | D34: BARRA ESTABILIZADORA | E34: EV1011 | F34: 0 | G34: 45967 | I34: Make/Buy | J34: 45968 | K34: CONTRATO | L34: AMX | M34: 45973 | N34: 45973 | O34: 45973 | P34: 1 | Q34: 1460 | R34: =Q34/89.23 -> 16.36221 | S34: =IFERROR(VLOOKUP(L34,'Responsáveis'!$A$3:$B$136,2,FALSE),"NE") -> Ana | U34: NÃO | V34: Concluído
A35: STL/PWT | B35: BRBCABA19 | C35: NR12 | D35: PROTEÇÃO | E35: EV1012 | F35: 0 | G35: 45967 | I35: Make | J35: 45968 | K35: CONTRATO | L35: MANUFACTURING | M35: 45968 | N35: 45968 | O35: 45968 | P35: 1 | Q35: 1828.58 | R35: =Q35/89.23 -> 20.492884 | S35: =IFERROR(VLOOKUP(L35,'Responsáveis'!$A$3:$B$136,2,FALSE),"NE") -> Ana | U35: NÃO | V35: Concluído
A36: STL/PWT | B36: BRBCABA19 | C36: - | D36: PROTEÇÃO DE BARREIRAS | E36: EV1013 | F36: 0 | G36: 45967 | I36: Make/Buy | J36: 45971 | K36: CONTRATO | L36: AMX | M36: 45973 | N36: 45973 | O36: 45973 | P36: 1 | Q36: 3105 | R36: =Q36/89.23 -> 34.797714 | S36: =IFERROR(VLOOKUP(L36,'Responsáveis'!$A$3:$B$136,2,FALSE),"NE") -> Ana | U36: NÃO | V36: Concluído
A37: STL/FIAT | B37: BRBCBBB13 | C37: - | D37: CHAPAS DE FIXAÇÃO | E37: EV1014 | F37: 0 | G37: 45967 | H37: Local de Entrega: Comau Tijolinho | I37: Make/Buy | J37: 45968 | K37: CONTRATO | L37: AMX | M37: 45976 | N37: 45976 | O37: 45976 | P37: 1 | Q37: 2106 | R37: =Q37/89.23 -> 23.601928 | S37: =IFERROR(VLOOKUP(L37,'Responsáveis'!$A$3:$B$136,2,FALSE),"NE") -> Ana | U37: NÃO | V37: Concluído
A38: STL/PWT | B38: BRBCABA19 | C38: - | D38: DIVERSOS | E38: EV1015 | F38: 0 | G38: 45968 | H38: 17/11 - Será enviado dia 18/11 | I38: Make/Buy | J38: 45971 | K38: CONTRATO | L38: IMECOR | M38: 45986 | N38: 45986 | O38: 45986 | P38: 1 | Q38: 6160 | R38: =Q38/89.23 -> 69.035078 | S38: =IFERROR(VLOOKUP(L38,'Responsáveis'!$A$3:$B$136,2,FALSE),"NE") -> Ana | U38: NÃO | V38: Concluído
A39: JEEP | B39: BRBRRBA18 | C39: - | D39: TASSELO | E39: EV1016 | F39: 0 | G39: 45968 | I39: Make/Buy | J39: 45971 | K39: CONTRATO | L39: IMECOR | M39: 45972 | N39: 45972 | P39: 1 | Q39: 720 | R39: =Q39/89.23 -> 8.0690351 | S39: =IFERROR(VLOOKUP(L39,'Responsáveis'!$A$3:$B$136,2,FALSE),"NE") -> Ana | U39: NÃO | V39: Concluído
A40: JEEP | B40: BRBCBBB10 | C40: FDA/FSA060T05 | D40: KIT MODIFICA | E40: EV1022 | F40: 0 | G40: 45972 | I40: Make/Buy | J40: 45972 | K40: CONTRATO | L40: IMECOR | M40: 45991 | N40: 45991 | O40: 45991 | P40: 1 | Q40: 8348.4 | R40: =Q40/89.23 -> 93.560462 | S40: =IFERROR(VLOOKUP(L40,'Responsáveis'!$A$3:$B$136,2,FALSE),"NE") -> Ana | U40: NÃO | V40: Concluído | W40: Pernambuco
...

Sheet Saturação
A1: Fornecedor | H1: Relação de fornecedores - Qualidade
A2: Nome | B2: Saturação | C2: Saturação % | D2: Capacidade | E2: Nota avaliação
A3: AC CORTE LASER EIRELI - ME | B3: =SUMIFS('Follow up'!R:R,'Follow up'!L:L,A3,'Follow up'!V:V,"Em andamento",'Follow up'!P:P,"<>100%") -> 0 | C3: =IFERROR(B3/D3,"0%") -> 0 | D3: 560.3 | E3: ='Avaliação - Fornecedores'!L2 -> 0.5 | H3: https://docs.google.com/spreadsheets/d/1jFup92_7xc7K-eGCUIbwIdcgOsyly2rWAEGh_VDpyUA/edit?gid=33980226#gid=33980226
A4: ADER | B4: =SUMIFS('Follow up'!R:R,'Follow up'!L:L,A4,'Follow up'!V:V,"Em andamento",'Follow up'!P:P,"<>100%") -> 0 | C4: =IFERROR(B4/D4,"0%") -> 0 | D4: 5603.5 | E4: ='Avaliação - Fornecedores'!L3 -> 0.83
A5: ADZ INDUSTRIA E COMERCIO LTDA | B5: =SUMIFS('Follow up'!R:R,'Follow up'!L:L,A5,'Follow up'!V:V,"Em andamento",'Follow up'!P:P,"<>100%") -> 0 | C5: =IFERROR(B5/D5,"0%") -> 0 | D5: 560.3 | E5: ='Avaliação - Fornecedores'!L4 -> 0.5
A6: AGES INDUSTRIA E SERVICOS LTDA
A7: ALFA EQUIPAMENTOS | B7: =SUMIFS('Follow up'!R:R,'Follow up'!L:L,A7,'Follow up'!V:V,"Em andamento",'Follow up'!P:P,"<>100%") -> 0 | C7: =IFERROR(B7/D7,"0%") -> 0 | D7: 560.3 | E7: ='Avaliação - Fornecedores'!L6 -> 0.9
A8: AMX | B8: =SUMIFS('Follow up'!R:R,'Follow up'!L:L,A8,'Follow up'!V:V,"Em andamento",'Follow up'!P:P,"<>100%") -> 1756.4945 | C8: =IFERROR(B8/D8,"0%") -> 0.31820552 | D8: ='Capacidade fornecedores'!B67 -> 5520 | E8: ='Avaliação - Fornecedores'!L7 -> 0.915
A9: AR SANTOS | B9: =SUMIFS('Follow up'!R:R,'Follow up'!L:L,A9,'Follow up'!V:V,"Em andamento",'Follow up'!P:P,"<>100%") -> 2996.5867 | C9: =IFERROR(B9/D9,"0%") -> 0.70144819 | D9: ='Capacidade fornecedores'!B297 -> 4272 | E9: ='Avaliação - Fornecedores'!L8 -> 0.81
A10: ARTE USINAGEM INDUSTRIAL LTDA. | B10: =SUMIFS('Follow up'!R:R,'Follow up'!L:L,A10,'Follow up'!V:V,"Em andamento",'Follow up'!P:P,"<>100%") -> 0 | C10: =IFERROR(B10/D10,"0%") -> 0 | D10: 560.3 | E10: ='Avaliação - Fornecedores'!L9 -> 0.59
A11: BGB | B11: =SUMIFS('Follow up'!R:R,'Follow up'!L:L,A11,'Follow up'!V:V,"Em andamento",'Follow up'!P:P,"<>100%") -> 5757.8169 | C11: =IFERROR(B11/D11,"0%") -> 1.6776856 | D11: ='Capacidade fornecedores'!B274 -> 3432 | E11: ='Avaliação - Fornecedores'!L10 -> 0.8
A12: BM MULTIMETAIS LTDA | B12: =SUMIFS('Follow up'!R:R,'Follow up'!L:L,A12,'Follow up'!V:V,"Em andamento",'Follow up'!P:P,"<>100%") -> 0 | C12: =IFERROR(B12/D12,"0%") -> 0 | D12: 3362.1 | E12: ='Avaliação - Fornecedores'!L11 -> 0.5
A13: BONFER FERRAMENTARIA | E13: ='Avaliação - Fornecedores'!L12
A14: BROVIND | B14: =SUMIFS('Follow up'!R:R,'Follow up'!L:L,A14,'Follow up'!V:V,"Em andamento",'Follow up'!P:P,"<>100%") -> 0 | C14: =IFERROR(B14/D14,"0%") -> 0 | D14: 1681 | E14: ='Avaliação - Fornecedores'!L13 -> 0
A15: BRUMA JATO | B15: =SUMIFS('Follow up'!R:R,'Follow up'!L:L,A15,'Follow up'!V:V,"Em andamento",'Follow up'!P:P,"<>100%") -> 0 | C15: =IFERROR(B15/D15,"0%") -> 0 | D15: 560.3 | E15: =#REF! -> #REF!
A16: C B A ASSUNCAO FERRAMENTARIA E DISP | B16: =SUMIFS('Follow up'!R:R,'Follow up'!L:L,A16,'Follow up'!V:V,"Em andamento",'Follow up'!P:P,"<>100%") -> 0 | C16: =IFERROR(B16/D16,"0%") -> 0 | D16: =50000/89.23 -> 560.34966 | E16: ='Avaliação - Fornecedores'!L14 -> 0 | F16: x
A17: C.HENRIQUE BODEMEIER & CIA LTDA | B17: =SUMIFS('Follow up'!R:R,'Follow up'!L:L,A17,'Follow up'!V:V,"Em andamento",'Follow up'!P:P,"<>100%") -> 0 | C17: =IFERROR(B17/D17,"0%") -> 0 | D17: 5603.5 | E17: ='Avaliação - Fornecedores'!L15 -> 0
A18: CALDEROL | B18: =SUMIFS('Follow up'!R:R,'Follow up'!L:L,A18,'Follow up'!V:V,"Em andamento",'Follow up'!P:P,"<>100%") -> 0 | C18: =IFERROR(B18/D18,"0%") -> 0 | D18: 1344.8 | E18: ='Avaliação - Fornecedores'!L16 -> 0.725
A19: CAM DO BRASIL CONSTRUCAO EQUIPAMENTOS MECANICOS LTDA | B19: =SUMIFS('Follow up'!R:R,'Follow up'!L:L,A19,'Follow up'!V:V,"Em andamento",'Follow up'!P:P,"<>100%") -> 0 | C19: =IFERROR(B19/D19,"0%") -> 0 | D19: 1120.7 | E19: ='Avaliação - Fornecedores'!L17
A20: CHRILU SOLUCOES ERGONOMICAS LTDA | B20: =SUMIFS('Follow up'!R:R,'Follow up'!L:L,A20,'Follow up'!V:V,"Em andamento",'Follow up'!P:P,"<>100%") -> 0 | C20: =IFERROR(B20/D20,"0%") -> 0 | D20: 1681 | E20: ='Avaliação - Fornecedores'!L18 -> 0.64
A21: COLLETTI INDUSTRIA E COMERCIO DE EQUIP. INDUSTRIAIS EIRELI | B21: =SUMIFS('Follow up'!R:R,'Follow up'!L:L,A21,'Follow up'!V:V,"Em andamento",'Follow up'!P:P,"<>100%") -> 0 | C21: =IFERROR(B21/D21,"0%") -> 0 | D21: 1681 | E21: ='Avaliação - Fornecedores'!L19 -> 0
A22: CONTRIC MODENA PAINÉIS E INSTALAÇÕE | B22: =SUMIFS('Follow up'!R:R,'Follow up'!L:L,A22,'Follow up'!V:V,"Em andamento",'Follow up'!P:P,"<>100%") -> 0 | C22: =IFERROR(B22/D22,"0%") -> 0 | D22: 11207 | E22: ='Avaliação - Fornecedores'!L20 -> 0
A23: COOP. DE TRAB. DOS PROD. DE ART. DE | B23: =SUMIFS('Follow up'!R:R,'Follow up'!L:L,A23,'Follow up'!V:V,"Em andamento",'Follow up'!P:P,"<>100%") -> 0 | C23: =IFERROR(B23/D23,"0%") -> 0 | D23: 3362.1 | E23: ='Avaliação - Fornecedores'!L21 -> 0
A24: COOPERFER | B24: =SUMIFS('Follow up'!R:R,'Follow up'!L:L,A24,'Follow up'!V:V,"Em andamento",'Follow up'!P:P,"<>100%") -> 0 | C24: =IFERROR(B24/D24,"0%") -> 0 | D24: 3362.1 | E24: ='Avaliação - Fornecedores'!L22 -> 0
A25: CORDELLA AUTOMAÇÃO LTDA | B25: =SUMIFS('Follow up'!R:R,'Follow up'!L:L,A25,'Follow up'!V:V,"Em andamento",'Follow up'!P:P,"<>100%") -> 0 | C25: =IFERROR(B25/D25,"0%") -> 0 | D25: 5603.5 | E25: ='Avaliação - Fornecedores'!L23 -> 0
A26: CORREMAQ | B26: =SUMIFS('Follow up'!R:R,'Follow up'!L:L,A26,'Follow up'!V:V,"Em andamento",'Follow up'!P:P,"<>100%") -> 0 | C26: =IFERROR(B26/D26,"0%") -> 0 | D26: 560.3 | E26: ='Avaliação - Fornecedores'!L24 -> 0.685
A27: CYDAK DO BRASIL LTDA | B27: =SUMIFS('Follow up'!R:R,'Follow up'!L:L,A27,'Follow up'!V:V,"Em andamento",'Follow up'!P:P,"<>100%") -> 0 | C27: =IFERROR(B27/D27,"0%") -> 0 | D27: 11207 | E27: ='Avaliação - Fornecedores'!L25 -> 0
A28: DINSE | B28: =SUMIFS('Follow up'!R:R,'Follow up'!L:L,A28,'Follow up'!V:V,"Em andamento",'Follow up'!P:P,"<>100%") -> 0 | C28: =IFERROR(B28/D28,"0%") -> 0 | D28: 5603.5 | E28: ='Avaliação - Fornecedores'!L26 -> 0
A29: DKFER SERVICOS DE USINAGEM LTDA | E29: ='Avaliação - Fornecedores'!L27
A30: DR PROMAQ INDUSTRIA E COMERCIO LTDA | B30: =SUMIFS('Follow up'!R:R,'Follow up'!L:L,A30,'Follow up'!V:V,"Em andamento",'Follow up'!P:P,"<>100%") -> 0 | C30: =IFERROR(B30/D30,"0%") -> 0 | D30: 4482.8 | E30: ='Avaliação - Fornecedores'!L28 -> 0
A31: DUREN | B31: =SUMIFS('Follow up'!R:R,'Follow up'!L:L,A31,'Follow up'!V:V,"Em andamento",'Follow up'!P:P,"<>100%") -> 7782.0687 | C31: =IFERROR(B31/D31,"0%") -> 1.3887871 | D31: 5603.5
A32: EBV | B32: =SUMIFS('Follow up'!R:R,'Follow up'!L:L,A32,'Follow up'!V:V,"Em andamento",'Follow up'!P:P,"<>100%") -> 0 | C32: =IFERROR(B32/D32,"0%") -> 0 | D32: 1120.7 | E32: ='Avaliação - Fornecedores'!L29 -> 0
A33: EDSON ARENA USINAGEM EIRELI | B33: =SUMIFS('Follow up'!R:R,'Follow up'!L:L,A33,'Follow up'!V:V,"Em andamento",'Follow up'!P:P,"<>100%") -> 0 | C33: =IFERROR(B33/D33,"0%") -> 0 | D33: 560.3 | E33: ='Avaliação - Fornecedores'!L30 -> 0
A34: EINTEGRA | B34: =SUMIFS('Follow up'!R:R,'Follow up'!L:L,A34,'Follow up'!V:V,"Em andamento",'Follow up'!P:P,"<>100%") -> 6844.2163 | C34: =IFERROR(B34/D34,"0%") -> 2.1936591 | D34: 3120 | E34: ='Avaliação - Fornecedores'!L31 -> 0.755
A35: EJP | B35: =SUMIFS('Follow up'!R:R,'Follow up'!L:L,A35,'Follow up'!V:V,"Em andamento",'Follow up'!P:P,"<>100%") -> 0 | C35: =IFERROR(B35/D35,"0%") -> 0 | D35: 560.3 | E35: ='Avaliação - Fornecedores'!L32 -> 0
A36: ESTAMOLD INDUSTRIA E COMERCIO LTDA - EPP | B36: =SUMIFS('Follow up'!R:R,'Follow up'!L:L,A36,'Follow up'!V:V,"Em andamento",'Follow up'!P:P,"<>100%") -> 0 | C36: =IFERROR(B36/D36,"0%") -> 0 | D36: 1120.7 | E36: ='Avaliação - Fornecedores'!L33 -> 0.65
A37: ETJ INDUSTRIA MECANICA DE PRECISAO | B37: =SUMIFS('Follow up'!R:R,'Follow up'!L:L,A37,'Follow up'!V:V,"Em andamento",'Follow up'!P:P,"<>100%") -> 0 | C37: =IFERROR(B37/D37,"0%") -> 0 | D37: 560.3 | E37: ='Avaliação - Fornecedores'!L34 -> 0
A38: FELIX INDUSTRIAL LTDA | B38: =SUMIFS('Follow up'!R:R,'Follow up'!L:L,A38,'Follow up'!V:V,"Em andamento",'Follow up'!P:P,"<>100%") -> 0 | C38: =IFERROR(B38/D38,"0%") -> 0 | D38: 896.6 | E38: ='Avaliação - Fornecedores'!L35 -> 0
A39: FERRAMENTARIA AMÉRICA LATINA | B39: =SUMIFS('Follow up'!R:R,'Follow up'!L:L,A39,'Follow up'!V:V,"Em andamento",'Follow up'!P:P,"<>100%") -> 0 | C39: =IFERROR(B39/D39,"0%") -> 0 | D39: 560.3 | E39: ='Avaliação - Fornecedores'!L36 -> 0.59
A40: FORTALE USINAGEM E FERRAMENTARIA LT | B40: =SUMIFS('Follow up'!R:R,'Follow up'!L:L,A40,'Follow up'!V:V,"Em andamento",'Follow up'!P:P,"<>100%") -> 0 | C40: =IFERROR(B40/D40,"0%") -> 0 | D40: 560.3 | E40: ='Avaliação - Fornecedores'!L37 -> 0.63
...

Sheet Capacidade fornecedores
A1: Imecor
A2: Fornecedor
A3: Imecor
A9: Notas
A10: 9 horas por máquina - CONV
A11: 10 horas por máquina - CNC | B11: Fresa convencional | E11: Fresa CNC | H11: Torno convencional | K11: Torno CNC | N11: Mandriladora | Q11: Retifica | T11: Calderaria
A12: 6 dias por semana | B12: 8 | E12: 2 | H12: 2 | K12: 1 | N12: 0 | Q12: 0 | T12: 10
A13: 24 dias por mês | B13: Carga diária | E13: Carga diária | H13: Carga diária | K13: Carga diária | N13: Carga diária | Q13: Carga diária | T13: Carga diária
B14: =8*18 -> 144 | E14: 18 | H14: =5*18 -> 90 | K14: 18 | N14: 18 | Q14: 0 | T14: =10*10 -> 100
B15: Carga semanal | E15: Carga semanal | H15: Carga semanal | K15: Carga semanal | N15: Carga semanal | Q15: Carga semanal | T15: Carga semanal
B16: =B14*6 -> 864 | E16: =E14*6 -> 108 | H16: =H14*6 -> 540 | K16: =K14*6 -> 108 | N16: =N14*6 -> 108 | Q16: =Q14*6 -> 0 | T16: =T14*6 -> 600
B17: Carga mensal | E17: Carga mensal | H17: Carga mensal | K17: Carga mensal | N17: Carga mensal | Q17: Carga mensal | T17: Carga mensal
A18: Saturação atual | B18: =B14*24 -> 3456 | E18: =E14*24 -> 432 | H18: =H14*24 -> 2160 | K18: =K14*24 -> 432 | N18: =N14*24 -> 432 | Q18: =Q14*24 -> 0 | T18: =T14*24 -> 2400
A19: =IFERROR(B23/B21,"0%") -> 1.2119084
B20: Horas | C20: Valor
A21: Total h/mês | B21: =SUM(B18+E18+H18+K18+N18+Q18+T18) -> 9312 | C21: =B21*B22 -> 831561.6
A22: Custo h | B22: 89.3
A23: Saturação atual | B23: ='Saturação'!B50 -> 11285.291 | C23: =B23*B22 -> 1007776.5
A24: UFINAP
A25: Fornecedor
A26: UFINAP
A32: Notas
A33: 9 horas por máquina - CONV
A34: 10 horas por máquina - CNC | B34: Fresa convencional | E34: Fresa CNC | H34: Torno convencional | K34: Torno CNC | N34: Mandriladora | Q34: Retifica | T34: Calderaria
A35: 6 dias por semana | B35: 4 | E35: 3 | H35: 3 | K35: 2 | N35: 2 | Q35: 2 | T35: 10
A36: 24 dias por mês | B36: Carga diária | E36: Carga diária | H36: Carga diária | K36: Carga diária | N36: Carga diária | Q36: Carga diária | T36: Carga diária
B37: =4*24 -> 96 | E37: =3*24 -> 72 | H37: =3*24 -> 72 | K37: =2*24 -> 48 | N37: =2*24 -> 48 | Q37: =2*9 -> 18 | T37: =10*12 -> 120
B38: Carga semanal | E38: Carga semanal | H38: Carga semanal | K38: Carga semanal | N38: Carga semanal | Q38: Carga semanal | T38: Carga semanal
B39: =B37*6 -> 576 | E39: =E37*6 -> 432 | H39: =H37*6 -> 432 | K39: =K37*6 -> 288 | N39: =N37*6 -> 288 | Q39: =Q37*6 -> 108 | T39: =T37*6 -> 720
B40: Carga mensal | E40: Carga mensal | H40: Carga mensal | K40: Carga mensal | N40: Carga mensal | Q40: Carga mensal | T40: Carga mensal
A41: Saturação atual | B41: =B37*24 -> 2304 | E41: =E37*24 -> 1728 | H41: =H37*24 -> 1728 | K41: =K37*24 -> 1152 | N41: =N37*24 -> 1152 | Q41: =Q37*24 -> 432 | T41: =T37*24 -> 2880
A42: =IFERROR(B46/B44,"0%") -> 1.0167973
B43: Horas | C43: Valor Total
A44: Total h/mês | B44: =SUM(B41+E41+H41+K41+N41+Q41+T41) -> 11376 | C44: =B44*B45 -> 1015876.8
A45: Custo h | B45: 89.3
A46: Saturação atual | B46: ='Saturação'!B130 -> 11567.086 | C46: =B46*B45 -> 1032940.8
A47: METROMEC
A48: Fornecedor
A49: METROMEC / AMX
A55: Notas
...

Sheet Avaliação - Fornecedores
A1: Fornecedor | B1: Qualidade | C1: Qualidade | D1: Cumprimento dos prazos | E1: Cumprimento dos prazos | F1: Suporte / Flexibilidade | G1: Suporte / Flexibilidade | H1: Conformidade documental | I1: Conformidade documental | J1: Adequação aos requisitos | K1: Adequação aos requisitos | L1: Classificação final
A2: AC CORTE LASER EIRELI - ME | B2: =C2*$O$16 -> 0.1 | C2: 0.5 | D2: =E2*$O$17 -> 0.15 | E2: 0.5 | F2: =G2*$O$18 -> 0.1 | G2: 0.5 | H2: =I2*$O$19 -> 0.05 | I2: 0.5 | J2: =K2*$O$20 -> 0.1 | K2: 0.5 | L2: =SUM(J2+H2+F2+D2+B2) -> 0.5
A3: ADER | B3: =C3*$O$16 -> 0.2 | C3: 1 | D3: =E3*$O$17 -> 0.24 | E3: 0.8 | F3: =G3*$O$18 -> 0.14 | G3: 0.7 | H3: =I3*$O$19 -> 0.09 | I3: 0.9 | J3: =K3*$O$20 -> 0.16 | K3: 0.8 | L3: =SUM(J3+H3+F3+D3+B3) -> 0.83
A4: ADZ INDUSTRIA E COMERCIO LTDA | B4: =C4*$O$16 -> 0.1 | C4: 0.5 | D4: =E4*$O$17 -> 0.15 | E4: 0.5 | F4: =G4*$O$18 -> 0.1 | G4: 0.5 | H4: =I4*$O$19 -> 0.05 | I4: 0.5 | J4: =K4*$O$20 -> 0.1 | K4: 0.5 | L4: =SUM(J4+H4+F4+D4+B4) -> 0.5
A5: AGES INDUSTRIA E SERVICOS LTDA | B5: =C5*$O$16 -> #VALUE! | C5: BLOQUEADO
A6: ALFA EQUIPAMENTOS | B6: =C6*$O$16 -> 0.16 | C6: 0.8 | D6: =E6*$O$17 -> 0.27 | E6: 0.9 | F6: =G6*$O$18 -> 0.2 | G6: 1 | H6: =I6*$O$19 -> 0.09 | I6: 0.9 | J6: =K6*$O$20 -> 0.18 | K6: 0.9 | L6: =SUM(J6+H6+F6+D6+B6) -> 0.9
A7: AMX | B7: =C7*$O$16 -> 0.18 | C7: 0.9 | D7: =E7*$O$17 -> 0.27 | E7: 0.9 | F7: =G7*$O$18 -> 0.19 | G7: 0.95 | H7: =I7*$O$19 -> 0.085 | I7: 0.85 | J7: =K7*$O$20 -> 0.19 | K7: 0.95 | L7: =SUM(J7+H7+F7+D7+B7) -> 0.915
A8: AR SANTOS | B8: =C8*$O$16 -> 0.17 | C8: 0.85 | D8: =E8*$O$17 -> 0.24 | E8: 0.8 | F8: =G8*$O$18 -> 0.17 | G8: 0.85 | H8: =I8*$O$19 -> 0.05 | I8: 0.5 | J8: =K8*$O$20 -> 0.18 | K8: 0.9 | L8: =SUM(J8+H8+F8+D8+B8) -> 0.81
A9: ARTE USINAGEM INDUSTRIAL LTDA. | B9: =C9*$O$16 -> 0.12 | C9: 0.6 | D9: =E9*$O$17 -> 0.18 | E9: 0.6 | F9: =G9*$O$18 -> 0.12 | G9: 0.6 | H9: =I9*$O$19 -> 0.06 | I9: 0.6 | J9: =K9*$O$20 -> 0.11 | K9: 0.55 | L9: =SUM(J9+H9+F9+D9+B9) -> 0.59
A10: BGB | B10: =C10*$O$16 -> 0.18 | C10: 0.9 | D10: =E10*$O$17 -> 0.24 | E10: 0.8 | F10: =G10*$O$18 -> 0.12 | G10: 0.6 | H10: =I10*$O$19 -> 0.08 | I10: 0.8 | J10: =K10*$O$20 -> 0.18 | K10: 0.9 | L10: =SUM(J10+H10+F10+D10+B10) -> 0.8
A11: BM MULTIMETAIS LTDA | B11: =C11*$O$16 -> 0.1 | C11: 0.5 | D11: =E11*$O$17 -> 0.15 | E11: 0.5 | F11: =G11*$O$18 -> 0.1 | G11: 0.5 | H11: =I11*$O$19 -> 0.05 | I11: 0.5 | J11: =K11*$O$20 -> 0.1 | K11: 0.5 | L11: =SUM(J11+H11+F11+D11+B11) -> 0.5
A12: BONFER FERRAMENTARIA | B12: =C12*$O$16 -> #VALUE! | C12: BLOQUEADO
A13: BROVIND DO BRASIL INDUSTRIA E COMER | B13: =C13*$O$16 -> 0 | D13: =E13*$O$17 -> 0 | F13: =G13*$O$18 -> 0 | H13: =I13*$O$19 -> 0 | J13: =K13*$O$20 -> 0 | L13: =SUM(J13+H13+F13+D13+B13) -> 0
A14: C B A ASSUNCAO FERRAMENTARIA E DISP | B14: =C14*$O$16 -> 0 | D14: =E14*$O$17 -> 0 | F14: =G14*$O$18 -> 0 | H14: =I14*$O$19 -> 0 | J14: =K14*$O$20 -> 0 | L14: =SUM(J14+H14+F14+D14+B14) -> 0 | N14: Atividade | O14: Peso
A15: C.HENRIQUE BODEMEIER & CIA LTDA | B15: =C15*$O$16 -> 0 | D15: =E15*$O$17 -> 0 | F15: =G15*$O$18 -> 0 | H15: =I15*$O$19 -> 0 | J15: =K15*$O$20 -> 0 | L15: =SUM(J15+H15+F15+D15+B15) -> 0
A16: CALDEROL - INDUSTRIA E COMERCIO EIR | B16: =C16*$O$16 -> 0.15 | C16: 0.75 | D16: =E16*$O$17 -> 0.195 | E16: 0.65 | F16: =G16*$O$18 -> 0.14 | G16: 0.7 | H16: =I16*$O$19 -> 0.08 | I16: 0.8 | J16: =K16*$O$20 -> 0.16 | K16: 0.8 | L16: =SUM(J16+H16+F16+D16+B16) -> 0.725 | N16: Qualidade | O16: 0.2
A17: CAM DO BRASIL CONSTRUCAO EQUIPAMENTOS MECANICOS LTDA | B17: =C17*$O$16 -> #VALUE! | C17: Fornecedor não sendo utilizado | N17: Cumprimento dos prazos | O17: 0.3
A18: CHRILU SOLUCOES ERGONOMICAS LTDA | B18: =C18*$O$16 -> 0.13 | C18: 0.65 | D18: =E18*$O$17 -> 0.18 | E18: 0.6 | F18: =G18*$O$18 -> 0.12 | G18: 0.6 | H18: =I18*$O$19 -> 0.07 | I18: 0.7 | J18: =K18*$O$20 -> 0.14 | K18: 0.7 | L18: =SUM(J18+H18+F18+D18+B18) -> 0.64 | N18: Suporte / Flexibilidade | O18: 0.2
A19: COLLETTI INDUSTRIA E COMERCIO DE EQUIP. INDUSTRIAIS EIRELI | B19: =C19*$O$16 -> 0 | D19: =E19*$O$17 -> 0 | F19: =G19*$O$18 -> 0 | H19: =I19*$O$19 -> 0 | J19: =K19*$O$20 -> 0 | L19: =SUM(J19+H19+F19+D19+B19) -> 0 | N19: Conformidade documentos | O19: 0.1
A20: CONTRIC MODENA PAINÉIS E INSTALAÇÕE | B20: =C20*$O$16 -> 0 | D20: =E20*$O$17 -> 0 | F20: =G20*$O$18 -> 0 | H20: =I20*$O$19 -> 0 | J20: =K20*$O$20 -> 0 | L20: =SUM(J20+H20+F20+D20+B20) -> 0 | N20: Adequação aos requisitos | O20: 0.2
A21: COOP. DE TRAB. DOS PROD. DE ART. DE | B21: =C21*$O$16 -> 0 | D21: =E21*$O$17 -> 0 | F21: =G21*$O$18 -> 0 | H21: =I21*$O$19 -> 0 | J21: =K21*$O$20 -> 0 | L21: =SUM(J21+H21+F21+D21+B21) -> 0
A22: COOPERFER | B22: =C22*$O$16 -> 0 | D22: =E22*$O$17 -> 0 | F22: =G22*$O$18 -> 0 | H22: =I22*$O$19 -> 0 | J22: =K22*$O$20 -> 0 | L22: =SUM(J22+H22+F22+D22+B22) -> 0
A23: CORDELLA AUTOMAÇÃO LTDA | B23: =C23*$O$16 -> 0 | D23: =E23*$O$17 -> 0 | F23: =G23*$O$18 -> 0 | H23: =I23*$O$19 -> 0 | J23: =K23*$O$20 -> 0 | L23: =SUM(J23+H23+F23+D23+B23) -> 0
A24: CORREMAQ | B24: =C24*$O$16 -> 0.14 | C24: 0.7 | D24: =E24*$O$17 -> 0.21 | E24: 0.7 | F24: =G24*$O$18 -> 0.14 | G24: 0.7 | H24: =I24*$O$19 -> 0.065 | I24: 0.65 | J24: =K24*$O$20 -> 0.13 | K24: 0.65 | L24: =SUM(J24+H24+F24+D24+B24) -> 0.685
A25: CYDAK DO BRASIL LTDA | B25: =C25*$O$16 -> 0 | D25: =E25*$O$17 -> 0 | F25: =G25*$O$18 -> 0 | H25: =I25*$O$19 -> 0 | J25: =K25*$O$20 -> 0 | L25: =SUM(J25+H25+F25+D25+B25) -> 0
A26: DINSE G.m.b.H. | B26: =C26*$O$16 -> 0 | D26: =E26*$O$17 -> 0 | F26: =G26*$O$18 -> 0 | H26: =I26*$O$19 -> 0 | J26: =K26*$O$20 -> 0 | L26: =SUM(J26+H26+F26+D26+B26) -> 0
A27: DKFER SERVICOS DE USINAGEM LTDA | B27: =C27*$O$16 -> #VALUE! | C27: BLOQUEADO
A28: DR PROMAQ INDUSTRIA E COMERCIO LTDA | B28: =C28*$O$16 -> 0 | D28: =E28*$O$17 -> 0 | F28: =G28*$O$18 -> 0 | H28: =I28*$O$19 -> 0 | J28: =K28*$O$20 -> 0 | L28: =SUM(J28+H28+F28+D28+B28) -> 0
A29: EBV | B29: =C29*$O$16 -> 0 | D29: =E29*$O$17 -> 0 | F29: =G29*$O$18 -> 0 | H29: =I29*$O$19 -> 0 | J29: =K29*$O$20 -> 0 | L29: =SUM(J29+H29+F29+D29+B29) -> 0
A30: EDSON ARENA USINAGEM EIRELI | B30: =C30*$O$16 -> 0 | D30: =E30*$O$17 -> 0 | F30: =G30*$O$18 -> 0 | H30: =I30*$O$19 -> 0 | J30: =K30*$O$20 -> 0 | L30: =SUM(J30+H30+F30+D30+B30) -> 0
A31: EINTEGRA ENGENHARIA, INTEGRACÃO E ROBÓTICA LTDA | B31: =C31*$O$16 -> 0.18 | C31: 0.9 | D31: =E31*$O$17 -> 0.195 | E31: 0.65 | F31: =G31*$O$18 -> 0.14 | G31: 0.7 | H31: =I31*$O$19 -> 0.08 | I31: 0.8 | J31: =K31*$O$20 -> 0.16 | K31: 0.8 | L31: =SUM(J31+H31+F31+D31+B31) -> 0.755
A32: EJP | B32: =C32*$O$16 -> 0 | D32: =E32*$O$17 -> 0 | F32: =G32*$O$18 -> 0 | H32: =I32*$O$19 -> 0 | J32: =K32*$O$20 -> 0 | L32: =SUM(J32+H32+F32+D32+B32) -> 0
A33: ESTAMOLD INDUSTRIA E COMERCIO LTDA - EPP | B33: =C33*$O$16 -> 0.14 | C33: 0.7 | D33: =E33*$O$17 -> 0.21 | E33: 0.7 | F33: =G33*$O$18 -> 0.11 | G33: 0.55 | H33: =I33*$O$19 -> 0.07 | I33: 0.7 | J33: =K33*$O$20 -> 0.12 | K33: 0.6 | L33: =SUM(J33+H33+F33+D33+B33) -> 0.65
A34: ETJ INDUSTRIA MECANICA DE PRECISAO | B34: =C34*$O$16 -> 0 | D34: =E34*$O$17 -> 0 | F34: =G34*$O$18 -> 0 | H34: =I34*$O$19 -> 0 | J34: =K34*$O$20 -> 0 | L34: =SUM(J34+H34+F34+D34+B34) -> 0
